<?xml version="1.0" encoding="utf-8"?>
<mujoco model="walker2d">
	<compiler angle="degree" coordinate="global" inertiafromgeom="true"></compiler>
	<default>
		<joint armature="0.01" damping="0.07989549180098501" limited="true"></joint>
		<geom conaffinity="0" condim="3" contype="1" density="1000" friction="0.8147994616380644 0.08396082553880645 0.09492126387333383" rgba="0.8 0.6 .4 1"></geom>
	</default>
	<option integrator="RK4" timestep="0.002"></option>
	<worldbody>
		<light cutoff="100" diffuse="1 1 1" dir="-0 0 -1.3" directional="true" exponent="1" pos="0 0 1.3" specular=".1 .1 .1"></light>
		<geom conaffinity="1" condim="3" name="floor" pos="0 0 0" rgba="0.8 0.9 0.8 1" size="35.00586048743965 49.664836966540456 36.05511737081397" type="plane" material="MatPlane"></geom>
		<body name="torso" pos="0 0 1.25">
			<camera name="track" mode="trackcom" pos="0 -3 1" xyaxes="1 0 0 0 0 1"></camera>
			<joint armature="0" axis="1 0 0" damping="0.0" limited="false" name="rootx" pos="0 0 0" stiffness="0.0" type="slide"></joint>
			<joint armature="0" axis="0 0 1" damping="0.0" limited="false" name="rootz" pos="0 0 0" ref="1.25" stiffness="0.0" type="slide"></joint>
			<joint armature="0" axis="0 1 0" damping="0.0" limited="false" name="rooty" pos="0 0 1.25" stiffness="0.0" type="hinge"></joint>
			<geom friction="0.8348712638611384" fromto="0 0 1.45 0 0 1.05" name="torso_geom" size="0.045967329957674066" type="capsule"></geom>
			<body name="thigh" pos="0 0 1.05">
				<joint axis="0 -1 0" name="thigh_joint" pos="0 0 1.05" range="-150 0" type="hinge"></joint>
				<geom friction="1.0310019949143967" fromto="0 0 1.05 0 0 0.6" name="thigh_geom" size="0.05728044212696785" type="capsule"></geom>
				<body name="leg" pos="0 0 0.35">
					<joint axis="0 -1 0" name="leg_joint" pos="0 0 0.6" range="-150 0" type="hinge"></joint>
					<geom friction="0.8052075468031734" fromto="0 0 0.6 0 0 0.1" name="leg_geom" size="0.02875524936744207" type="capsule"></geom>
					<body name="foot" pos="0.2/2 0 0.1">
						<joint axis="0 -1 0" name="foot_joint" pos="0 0 0.1" range="-45 45" type="hinge"></joint>
						<geom friction="1.1395113796010958" fromto="-0.0 0 0.1 0.2 0 0.1" name="foot_geom" size="0.07153712209053889" type="capsule"></geom>
					</body>
				</body>
			</body>
			<body name="thigh_left" pos="0 0 1.05">
				<joint axis="0 -1 0" name="thigh_left_joint" pos="0 0 1.05" range="-150 0" type="hinge"></joint>
				<geom friction="1.1110662131805047" fromto="0 0 1.05 0 0 0.6" name="thigh_left_geom" rgba=".7 .3 .6 1" size="0.046713731773223535" type="capsule"></geom>
				<body name="leg_left" pos="0 0 0.35">
					<joint axis="0 -1 0" name="leg_left_joint" pos="0 0 0.6" range="-150 0" type="hinge"></joint>
					<geom friction="0.9865834800884603" fromto="0 0 0.6 0 0 0.1" name="leg_left_geom" rgba=".7 .3 .6 1" size="0.043858533109927204" type="capsule"></geom>
					<body name="foot_left" pos="0.2/2 0 0.1">
						<joint axis="0 -1 0" name="foot_left_joint" pos="0 0 0.1" range="-45 45" type="hinge"></joint>
						<geom friction="0.7931216742014526" fromto="-0.0 0 0.1 0.2 0 0.1" name="foot_left_geom" rgba=".7 .3 .6 1" size="0.07365697797155475" type="capsule"></geom>
					</body>
				</body>
			</body>
		</body>
	</worldbody>
	<actuator>
		<motor ctrllimited="true" ctrlrange="-1.0 1.0" gear="100" joint="thigh_joint"></motor>
		<motor ctrllimited="true" ctrlrange="-1.0 1.0" gear="100" joint="leg_joint"></motor>
		<motor ctrllimited="true" ctrlrange="-1.0 1.0" gear="100" joint="foot_joint"></motor>
		<motor ctrllimited="true" ctrlrange="-1.0 1.0" gear="100" joint="thigh_left_joint"></motor>
		<motor ctrllimited="true" ctrlrange="-1.0 1.0" gear="100" joint="leg_left_joint"></motor>
		<motor ctrllimited="true" ctrlrange="-1.0 1.0" gear="100" joint="foot_left_joint"></motor>
	</actuator>
	<asset>
		<texture type="skybox" builtin="gradient" rgb1=".4 .5 .6" rgb2="0 0 0" width="100" height="100"></texture>
		<texture builtin="flat" height="1278" mark="cross" markrgb="1 1 1" name="texgeom" random="0.01" rgb1="0.8 0.6 0.4" rgb2="0.8 0.6 0.4" type="cube" width="127"></texture>
		<texture builtin="checker" height="100" name="texplane" rgb1="0 0 0" rgb2="0.8 0.8 0.8" type="2d" width="100"></texture>
		<material name="MatPlane" reflectance="0.5" shininess="1" specular="1" texrepeat="60 60" texture="texplane"></material>
		<material name="geom" texture="texgeom" texuniform="true"></material>
	</asset>
</mujoco>