<?xml version="1.0" encoding="utf-8"?>
<mujoco model="humanoid">
	<compiler angle="degree" inertiafromgeom="true"></compiler>
	<default>
		<joint armature="1" damping="0.9471955748178388" limited="true"></joint>
		<geom conaffinity="1" condim="1" contype="1" margin="0.001" material="geom" rgba="0.8 0.6 .4 1"></geom>
		<motor ctrllimited="true" ctrlrange="-.4 .4"></motor>
	</default>
	<option integrator="RK4" iterations="50" solver="PGS" timestep="0.003"></option>
	<size nkey="5" nuser_geom="1"></size>
	<visual>
		<map fogend="5" fogstart="3"></map>
	</visual>
	<asset>
		<texture builtin="gradient" height="100" rgb1=".4 .5 .6" rgb2="0 0 0" type="skybox" width="100"></texture>
		<texture builtin="flat" height="1278" mark="cross" markrgb="1 1 1" name="texgeom" random="0.01" rgb1="0.8 0.6 0.4" rgb2="0.8 0.6 0.4" type="cube" width="127"></texture>
		<texture builtin="checker" height="100" name="texplane" rgb1="0 0 0" rgb2="0.8 0.8 0.8" type="2d" width="100"></texture>
		<material name="MatPlane" reflectance="0.5" shininess="1" specular="1" texrepeat="60 60" texture="texplane"></material>
		<material name="geom" texture="texgeom" texuniform="true"></material>
	</asset>
	<worldbody>
		<light cutoff="100" diffuse="1 1 1" dir="-0 0 -1.3" directional="true" exponent="1" pos="0 0 1.3" specular=".1 .1 .1"></light>
		<geom condim="3" friction="0.8618289307639078 0.0754197955941092 0.09703449673989287" material="MatPlane" name="floor" pos="0 0 0" rgba="0.8 0.9 0.8 1" size="21.137713676670423 21.36014853342698 0.13829877092449544" type="plane"></geom>
		<body name="torso" pos="0 0 1.4">
			<camera name="track" mode="trackcom" pos="0 -4 0" xyaxes="1 0 0 0 0 1"></camera>
			<joint armature="0" damping="0.0" limited="false" name="root" pos="0 0 0" stiffness="0.0" type="free"></joint>
			<geom fromto="0 -.07 0 0 .07 0" name="torso1" size="0.08456927133862718" type="capsule"></geom>
			<geom name="head" pos="0 0 .19" size="0.1068038721996186" type="sphere" user="258"></geom>
			<geom fromto="-.01 -.06 -.12 -.01 .06 -.12" name="uwaist" size="0.06296141003497199" type="capsule"></geom>
			<body name="lwaist" pos="-.01 0 -0.260" quat="1.000 0 -0.002 0">
				<geom fromto="0 -.06 0 0 .06 0" name="lwaist" size="0.07550452791260541" type="capsule"></geom>
				<joint armature="0.02" axis="0 0 1" damping="6.152937841433178" name="abdomen_z" pos="0 0 0.065" range="-45 45" stiffness="15.040735290423806" type="hinge"></joint>
				<joint armature="0.02" axis="0 1 0" damping="4.190623777960393" name="abdomen_y" pos="0 0 0.065" range="-75 30" stiffness="8.105616227660216" type="hinge"></joint>
				<body name="pelvis" pos="0 0 -0.165" quat="1.000 0 -0.002 0">
					<joint armature="0.02" axis="1 0 0" damping="4.161446089646637" name="abdomen_x" pos="0 0 0.1" range="-35 35" stiffness="8.03291550448182" type="hinge"></joint>
					<geom fromto="-.02 -.07 0 -.02 .07 0" name="butt" size="0.0731347044971595" type="capsule"></geom>
					<body name="right_thigh" pos="0 -0.1 -0.04">
						<joint armature="0.01" axis="1 0 0" damping="5.824827447606764" name="right_hip_x" pos="0 0 0" range="-25 5" stiffness="12.367099950915332" type="hinge"></joint>
						<joint armature="0.01" axis="0 0 1" damping="5.100210545038295" name="right_hip_z" pos="0 0 0" range="-60 35" stiffness="12.302133573332096" type="hinge"></joint>
						<joint armature="0.0080" axis="0 1 0" damping="5.927571527225641" name="right_hip_y" pos="0 0 0" range="-110 20" stiffness="19.64954724861661" type="hinge"></joint>
						<geom fromto="0 0 0 0 0.01 -.34" name="right_thigh1" size="0.07632779289203952" type="capsule"></geom>
						<body name="right_shin" pos="0 0.01 -0.403">
							<joint armature="0.0060" axis="0 -1 0" name="right_knee" pos="0 0 .02" range="-160 -2" type="hinge"></joint>
							<geom fromto="0 0 0 0 0 -.3" name="right_shin1" size="0.050881770037889705" type="capsule"></geom>
							<body name="right_foot" pos="0 0 -0.45">
								<geom name="right_foot" pos="0 0 0.1" size="0.09060607804790619" type="sphere" user="0"></geom>
							</body>
						</body>
					</body>
					<body name="left_thigh" pos="0 0.1 -0.04">
						<joint armature="0.01" axis="-1 0 0" damping="5.702713669669369" name="left_hip_x" pos="0 0 0" range="-25 5" stiffness="12.008422590452511" type="hinge"></joint>
						<joint armature="0.01" axis="0 0 -1" damping="4.017154376311446" name="left_hip_z" pos="0 0 0" range="-60 35" stiffness="10.29229483415568" type="hinge"></joint>
						<joint armature="0.01" axis="0 1 0" damping="5.718800516878515" name="left_hip_y" pos="0 0 0" range="-110 20" stiffness="17.801732022256523" type="hinge"></joint>
						<geom fromto="0 0 0 0 -0.01 -.34" name="left_thigh1" size="0.04776690185628179" type="capsule"></geom>
						<body name="left_shin" pos="0 -0.01 -0.403">
							<joint armature="0.0060" axis="0 -1 0" name="left_knee" pos="0 0 .02" range="-160 -2" stiffness="0.9248684269636797" type="hinge"></joint>
							<geom fromto="0 0 0 0 0 -.3" name="left_shin1" size="0.06254578525224945" type="capsule"></geom>
							<body name="left_foot" pos="0 0 -0.45">
								<geom name="left_foot" type="sphere" size="0.09214844965021796" pos="0 0 0.1" user="0"></geom>
							</body>
						</body>
					</body>
				</body>
			</body>
			<body name="right_upper_arm" pos="0 -0.17 0.06">
				<joint armature="0.0068" axis="2 1 1" name="right_shoulder1" pos="0 0 0" range="-85 60" stiffness="1.1495377438419" type="hinge"></joint>
				<joint armature="0.0051" axis="0 -1 1" name="right_shoulder2" pos="0 0 0" range="-85 60" stiffness="1.2912959083760944" type="hinge"></joint>
				<geom fromto="0 0 0 .16 -.16 -.16" name="right_uarm1" size="0.029896564236841856 0.12075819506835961" type="capsule"></geom>
				<body name="right_lower_arm" pos=".18 -.18 -.18">
					<joint armature="0.0028" axis="0 -1 1" name="right_elbow" pos="0 0 0" range="-90 50" stiffness="0.0" type="hinge"></joint>
					<geom fromto="0.01 0.01 0.01 .17 .17 .17" name="right_larm" size="0.03163376653471569" type="capsule"></geom>
					<geom name="right_hand" pos=".18 .18 .18" size="0.03139334444704493" type="sphere"></geom>
					<camera pos="0 0 0"></camera>
				</body>
			</body>
			<body name="left_upper_arm" pos="0 0.17 0.06">
				<joint armature="0.0068" axis="2 -1 1" name="left_shoulder1" pos="0 0 0" range="-60 85" stiffness="1.1011868171069232" type="hinge"></joint>
				<joint armature="0.0051" axis="0 1 1" name="left_shoulder2" pos="0 0 0" range="-60 85" stiffness="0.9818500216668113" type="hinge"></joint>
				<geom fromto="0 0 0 .16 .16 -.16" name="left_uarm1" size="0.04034677260069566 0.18237398273954902" type="capsule"></geom>
				<body name="left_lower_arm" pos=".18 .18 -.18">
					<joint armature="0.0028" axis="0 -1 -1" name="left_elbow" pos="0 0 0" range="-90 50" stiffness="0.0" type="hinge"></joint>
					<geom fromto="0.01 -0.01 0.01 .17 -.17 .17" name="left_larm" size="0.03982078414795652" type="capsule"></geom>
					<geom name="left_hand" pos=".18 -.18 .18" size="0.03288352435230992" type="sphere"></geom>
				</body>
			</body>
		</body>
	</worldbody>
	<tendon>
		<fixed name="left_hipknee">
			<joint coef="-1" joint="left_hip_y"></joint>
			<joint coef="1" joint="left_knee"></joint>
		</fixed>
		<fixed name="right_hipknee">
			<joint coef="-1" joint="right_hip_y"></joint>
			<joint coef="1" joint="right_knee"></joint>
		</fixed>
	</tendon>
	<actuator>
		<motor gear="100" joint="abdomen_y" name="abdomen_y"></motor>
		<motor gear="100" joint="abdomen_z" name="abdomen_z"></motor>
		<motor gear="100" joint="abdomen_x" name="abdomen_x"></motor>
		<motor gear="100" joint="right_hip_x" name="right_hip_x"></motor>
		<motor gear="100" joint="right_hip_z" name="right_hip_z"></motor>
		<motor gear="300" joint="right_hip_y" name="right_hip_y"></motor>
		<motor gear="200" joint="right_knee" name="right_knee"></motor>
		<motor gear="100" joint="left_hip_x" name="left_hip_x"></motor>
		<motor gear="100" joint="left_hip_z" name="left_hip_z"></motor>
		<motor gear="300" joint="left_hip_y" name="left_hip_y"></motor>
		<motor gear="200" joint="left_knee" name="left_knee"></motor>
		<motor gear="25" joint="right_shoulder1" name="right_shoulder1"></motor>
		<motor gear="25" joint="right_shoulder2" name="right_shoulder2"></motor>
		<motor gear="25" joint="right_elbow" name="right_elbow"></motor>
		<motor gear="25" joint="left_shoulder1" name="left_shoulder1"></motor>
		<motor gear="25" joint="left_shoulder2" name="left_shoulder2"></motor>
		<motor gear="25" joint="left_elbow" name="left_elbow"></motor>
	</actuator>
</mujoco>