<?xml version="1.0" encoding="utf-8"?>
<mujoco model="humanoid">
	<compiler angle="degree" inertiafromgeom="true"></compiler>
	<default>
		<joint armature="1" damping="0.980085918497664" limited="true"></joint>
		<geom conaffinity="1" condim="1" contype="1" margin="0.001" material="geom" rgba="0.8 0.6 .4 1"></geom>
		<motor ctrllimited="true" ctrlrange="-.4 .4"></motor>
	</default>
	<option integrator="RK4" iterations="50" solver="PGS" timestep="0.003"></option>
	<size nkey="5" nuser_geom="1"></size>
	<visual>
		<map fogend="5" fogstart="3"></map>
	</visual>
	<asset>
		<texture builtin="gradient" height="100" rgb1=".4 .5 .6" rgb2="0 0 0" type="skybox" width="100"></texture>
		<texture builtin="flat" height="1278" mark="cross" markrgb="1 1 1" name="texgeom" random="0.01" rgb1="0.8 0.6 0.4" rgb2="0.8 0.6 0.4" type="cube" width="127"></texture>
		<texture builtin="checker" height="100" name="texplane" rgb1="0 0 0" rgb2="0.8 0.8 0.8" type="2d" width="100"></texture>
		<material name="MatPlane" reflectance="0.5" shininess="1" specular="1" texrepeat="60 60" texture="texplane"></material>
		<material name="geom" texture="texgeom" texuniform="true"></material>
	</asset>
	<worldbody>
		<light cutoff="100" diffuse="1 1 1" dir="-0 0 -1.3" directional="true" exponent="1" pos="0 0 1.3" specular=".1 .1 .1"></light>
		<geom condim="3" friction="0.9573456678860701 0.10358866642866359 0.10083903045944789" material="MatPlane" name="floor" pos="0 0 0" rgba="0.8 0.9 0.8 1" size="19.16475809475245 20.087693116435386 0.12697816353300187" type="plane"></geom>
		<body name="torso" pos="0 0 1.4">
			<camera name="track" mode="trackcom" pos="0 -4 0" xyaxes="1 0 0 0 0 1"></camera>
			<joint armature="0" damping="0.0" limited="false" name="root" pos="0 0 0" stiffness="0.0" type="free"></joint>
			<geom fromto="0 -.07 0 0 .07 0" name="torso1" size="0.07244020045264164" type="capsule"></geom>
			<geom name="head" pos="0 0 .19" size="0.09278731032861322" type="sphere" user="258"></geom>
			<geom fromto="-.01 -.06 -.12 -.01 .06 -.12" name="uwaist" size="0.06070788247737845" type="capsule"></geom>
			<body name="lwaist" pos="-.01 0 -0.260" quat="1.000 0 -0.002 0">
				<geom fromto="0 -.06 0 0 .06 0" name="lwaist" size="0.0571225406551342" type="capsule"></geom>
				<joint armature="0.02" axis="0 0 1" damping="5.06203599300978" name="abdomen_z" pos="0 0 0.065" range="-45 45" stiffness="20.451549570424675" type="hinge"></joint>
				<joint armature="0.02" axis="0 1 0" damping="5.108267749044019" name="abdomen_y" pos="0 0 0.065" range="-75 30" stiffness="9.71786371404116" type="hinge"></joint>
				<body name="pelvis" pos="0 0 -0.165" quat="1.000 0 -0.002 0">
					<joint armature="0.02" axis="1 0 0" damping="5.198147274815216" name="abdomen_x" pos="0 0 0.1" range="-35 35" stiffness="9.696080599482592" type="hinge"></joint>
					<geom fromto="-.02 -.07 0 -.02 .07 0" name="butt" size="0.09015410073697415" type="capsule"></geom>
					<body name="right_thigh" pos="0 -0.1 -0.04">
						<joint armature="0.01" axis="1 0 0" damping="4.967716696453119" name="right_hip_x" pos="0 0 0" range="-25 5" stiffness="10.047519850735025" type="hinge"></joint>
						<joint armature="0.01" axis="0 0 1" damping="5.144968223186391" name="right_hip_z" pos="0 0 0" range="-60 35" stiffness="10.485902349691294" type="hinge"></joint>
						<joint armature="0.0080" axis="0 1 0" damping="4.906650445354193" name="right_hip_y" pos="0 0 0" range="-110 20" stiffness="20.092133749524464" type="hinge"></joint>
						<geom fromto="0 0 0 0 0.01 -.34" name="right_thigh1" size="0.05775082549836428" type="capsule"></geom>
						<body name="right_shin" pos="0 0.01 -0.403">
							<joint armature="0.0060" axis="0 -1 0" name="right_knee" pos="0 0 .02" range="-160 -2" type="hinge"></joint>
							<geom fromto="0 0 0 0 0 -.3" name="right_shin1" size="0.050410453007475584" type="capsule"></geom>
							<body name="right_foot" pos="0 0 -0.45">
								<geom name="right_foot" pos="0 0 0.1" size="0.07802491595968539" type="sphere" user="0"></geom>
							</body>
						</body>
					</body>
					<body name="left_thigh" pos="0 0.1 -0.04">
						<joint armature="0.01" axis="-1 0 0" damping="5.09656701098036" name="left_hip_x" pos="0 0 0" range="-25 5" stiffness="10.388557876835891" type="hinge"></joint>
						<joint armature="0.01" axis="0 0 -1" damping="5.178973420301966" name="left_hip_z" pos="0 0 0" range="-60 35" stiffness="10.411034671082557" type="hinge"></joint>
						<joint armature="0.01" axis="0 1 0" damping="4.817349967489843" name="left_hip_y" pos="0 0 0" range="-110 20" stiffness="20.56777859449147" type="hinge"></joint>
						<geom fromto="0 0 0 0 -0.01 -.34" name="left_thigh1" size="0.06156917215140873" type="capsule"></geom>
						<body name="left_shin" pos="0 -0.01 -0.403">
							<joint armature="0.0060" axis="0 -1 0" name="left_knee" pos="0 0 .02" range="-160 -2" stiffness="0.9637938435661004" type="hinge"></joint>
							<geom fromto="0 0 0 0 0 -.3" name="left_shin1" size="0.04764287014362561" type="capsule"></geom>
							<body name="left_foot" pos="0 0 -0.45">
								<geom name="left_foot" type="sphere" size="0.07512022768255819" pos="0 0 0.1" user="0"></geom>
							</body>
						</body>
					</body>
				</body>
			</body>
			<body name="right_upper_arm" pos="0 -0.17 0.06">
				<joint armature="0.0068" axis="2 1 1" name="right_shoulder1" pos="0 0 0" range="-85 60" stiffness="1.0312612278984035" type="hinge"></joint>
				<joint armature="0.0051" axis="0 -1 1" name="right_shoulder2" pos="0 0 0" range="-85 60" stiffness="1.0350177566407655" type="hinge"></joint>
				<geom fromto="0 0 0 .16 -.16 -.16" name="right_uarm1" size="0.0403377847156042 0.15770221563193096" type="capsule"></geom>
				<body name="right_lower_arm" pos=".18 -.18 -.18">
					<joint armature="0.0028" axis="0 -1 1" name="right_elbow" pos="0 0 0" range="-90 50" stiffness="0.0" type="hinge"></joint>
					<geom fromto="0.01 0.01 0.01 .17 .17 .17" name="right_larm" size="0.031482423615656875" type="capsule"></geom>
					<geom name="right_hand" pos=".18 .18 .18" size="0.04016098789178226" type="sphere"></geom>
					<camera pos="0 0 0"></camera>
				</body>
			</body>
			<body name="left_upper_arm" pos="0 0.17 0.06">
				<joint armature="0.0068" axis="2 -1 1" name="left_shoulder1" pos="0 0 0" range="-60 85" stiffness="0.9840047417714971" type="hinge"></joint>
				<joint armature="0.0051" axis="0 1 1" name="left_shoulder2" pos="0 0 0" range="-60 85" stiffness="1.0337569520798549" type="hinge"></joint>
				<geom fromto="0 0 0 .16 .16 -.16" name="left_uarm1" size="0.041298439998941915 0.16767853693848708" type="capsule"></geom>
				<body name="left_lower_arm" pos=".18 .18 -.18">
					<joint armature="0.0028" axis="0 -1 -1" name="left_elbow" pos="0 0 0" range="-90 50" stiffness="0.0" type="hinge"></joint>
					<geom fromto="0.01 -0.01 0.01 .17 -.17 .17" name="left_larm" size="0.03057891992315115" type="capsule"></geom>
					<geom name="left_hand" pos=".18 -.18 .18" size="0.04158205591443965" type="sphere"></geom>
				</body>
			</body>
		</body>
	</worldbody>
	<tendon>
		<fixed name="left_hipknee">
			<joint coef="-1" joint="left_hip_y"></joint>
			<joint coef="1" joint="left_knee"></joint>
		</fixed>
		<fixed name="right_hipknee">
			<joint coef="-1" joint="right_hip_y"></joint>
			<joint coef="1" joint="right_knee"></joint>
		</fixed>
	</tendon>
	<actuator>
		<motor gear="100" joint="abdomen_y" name="abdomen_y"></motor>
		<motor gear="100" joint="abdomen_z" name="abdomen_z"></motor>
		<motor gear="100" joint="abdomen_x" name="abdomen_x"></motor>
		<motor gear="100" joint="right_hip_x" name="right_hip_x"></motor>
		<motor gear="100" joint="right_hip_z" name="right_hip_z"></motor>
		<motor gear="300" joint="right_hip_y" name="right_hip_y"></motor>
		<motor gear="200" joint="right_knee" name="right_knee"></motor>
		<motor gear="100" joint="left_hip_x" name="left_hip_x"></motor>
		<motor gear="100" joint="left_hip_z" name="left_hip_z"></motor>
		<motor gear="300" joint="left_hip_y" name="left_hip_y"></motor>
		<motor gear="200" joint="left_knee" name="left_knee"></motor>
		<motor gear="25" joint="right_shoulder1" name="right_shoulder1"></motor>
		<motor gear="25" joint="right_shoulder2" name="right_shoulder2"></motor>
		<motor gear="25" joint="right_elbow" name="right_elbow"></motor>
		<motor gear="25" joint="left_shoulder1" name="left_shoulder1"></motor>
		<motor gear="25" joint="left_shoulder2" name="left_shoulder2"></motor>
		<motor gear="25" joint="left_elbow" name="left_elbow"></motor>
	</actuator>
</mujoco>