<?xml version="1.0" encoding="utf-8"?>
<mujoco model="inverted pendulum">
	<compiler inertiafromgeom="true"></compiler>
	<default>
		<joint armature="0" damping="1.284962193238656" limited="true"></joint>
		<geom contype="0" friction="1.1105607902071029 0.12552421436363437 0.1289952948476419" rgba="0.7 0.7 0 1"></geom>
		<tendon></tendon>
		<motor ctrlrange="-3 3"></motor>
	</default>
	<option gravity="0 0 -9.81" integrator="RK4" timestep="0.02"></option>
	<size nstack="3000"></size>
	<worldbody>
		<geom name="rail" pos="0 0 0" quat="0.707 0 0.707 0" rgba="0.3 0.3 0.7 1" size="0.01941376601105553 0.9220717845481241" type="capsule"></geom>
		<body name="cart" pos="0 0 0">
			<joint axis="1 0 0" limited="true" name="slider" pos="0 0 0" range="-1 1" type="slide"></joint>
			<geom name="cart" pos="0 0 0" quat="0.707 0 0.707 0" size="0.07506836428863317 0.08299153783912287" type="capsule"></geom>
			<body name="pole" pos="0 0 0">
				<joint axis="0 1 0" name="hinge" pos="0 0 0" limited="false" range="-90 90" type="hinge"></joint>
				<geom fromto="0 0 0 0.001 0 0.6" name="cpole" rgba="0 0.7 0.7 1" size="0.04186451031348067 0.316571170170305" type="capsule"></geom>
			</body>
		</body>
	</worldbody>
	<actuator>
		<motor gear="100" joint="slider" name="slide"></motor>
	</actuator>
</mujoco>